Workbook

Sheet Raw Data
A1: Ride ID | B1: Date | C1: Pickup Location | D1: Drop-off Location | E1: Fare | F1: Payment Method | G1: Ride Status | H1: Rating
A2: R001 | B2: 21-08-2026 | C2: Gulberg | D2: DHA | E2: 713 | F2: Cash | G2: Completed | H2: 5
A3: R002 | B3: 04-08-2026 | C3: Gulberg | D3: Askari | E3: 215 | F3: Cash | G3: Completed | H3: 3
A4: R003 | B4: 17-08-2026 | C4: Lahore | D4: Cantt | E4: 1009 | F4: Cash | G4: Completed | H4: 4
A5: R004 | B5: 26-08-2026 | C5: Lahore | D5: Model Town | E5: 1015 | F5: Card | G5: Completed | H5: 3
A6: R005 | B6: 25-08-2026 | C6: Bahria Town | D6: Gulberg | E6: 339 | F6: Card | G6: Completed | H6: 4
A7: R006 | B7: 20-08-2026 | C7: Johar Town | D7: DHA | E7: 1090 | F7: Wallet | G7: Completed | H7: 4
A8: R007 | B8: 03-08-2026 | C8: Johar Town | D8: Faisal Town | E8: 543 | F8: Wallet | G8: Completed | H8: 5
A9: R008 | B9: 08-08-2026 | C9: Johar Town | D9: Gulberg | E9: 626 | F9: Cash | G9: Completed | H9: 4
A10: R009 | B10: 21-08-2026 | C10: Bahria Town | D10: Model Town | E10: 908 | F10: Card | G10: Completed | H10: 4
A11: R010 | B11: 23-08-2026 | C11: Gulberg | D11: Model Town | E11: 651 | F11: Cash | G11: Completed | H11: 4
A12: R011 | B12: 30-08-2026 | C12: Model Town | D12: Faisal Town | E12: 264 | F12: Cash | G12: Cancelled
A13: R012 | B13: 26-08-2026 | C13: Bahria Town | D13: Askari | E13: 698 | F13: Cash | G13: Completed | H13: 5
A14: R013 | B14: 29-08-2026 | C14: Bahria Town | D14: Cantt | E14: 1172 | F14: Card | G14: Cancelled
A15: R014 | B15: 21-08-2026 | C15: Iqbal Town | D15: Model Town | E15: 692 | F15: Cash | G15: Completed | H15: 5
A16: R015 | B16: 18-08-2026 | C16: Johar Town | D16: Askari | E16: 967 | F16: Card | G16: Completed | H16: 3
A17: R016 | B17: 17-08-2026 | C17: Iqbal Town | D17: Gulberg | E17: 246 | F17: Cash | G17: Completed | H17: 3
A18: R017 | B18: 26-08-2026 | C18: Wapda Town | D18: Gulberg | E18: 938 | F18: Card | G18: Completed | H18: 4
A19: R018 | B19: 17-08-2026 | C19: Johar Town | D19: DHA | E19: 384 | F19: Wallet | G19: Cancelled
A20: R019 | B20: 25-08-2026 | C20: Johar Town | D20: Faisal Town | E20: 378 | F20: Card | G20: Completed | H20: 4
A21: R020 | B21: 01-08-2026 | C21: Johar Town | D21: Model Town | E21: 1189 | F21: Cash | G21: Cancelled
A22: R021 | B22: 10-08-2026 | C22: Model Town | D22: Model Town | E22: 915 | F22: Cash | G22: Completed | H22: 5
A23: R022 | B23: 30-08-2026 | C23: Lahore | D23: Faisal Town | E23: 1150 | F23: Cash | G23: Completed | H23: 4
A24: R023 | B24: 29-08-2026 | C24: Johar Town | D24: Cantt | E24: 268 | F24: Cash | G24: Cancelled
A25: R024 | B25: 03-08-2026 | C25: Gulberg | D25: Airport | E25: 291 | F25: Wallet | G25: Completed | H25: 3
A26: R025 | B26: 22-08-2026 | C26: Iqbal Town | D26: Model Town | E26: 692 | F26: Wallet | G26: Cancelled
A27: R026 | B27: 14-08-2026 | C27: Model Town | D27: Cantt | E27: 788 | F27: Card | G27: Cancelled
A28: R027 | B28: 21-08-2026 | C28: Bahria Town | D28: Airport | E28: 1074 | F28: Cash | G28: Completed | H28: 3
A29: R028 | B29: 11-08-2026 | C29: Lahore | D29: Cantt | E29: 601 | F29: Cash | G29: Completed | H29: 5
A30: R029 | B30: 02-08-2026 | C30: Model Town | D30: Gulberg | E30: 214 | F30: Card | G30: Completed | H30: 3
A31: R030 | B31: 09-08-2026 | C31: Iqbal Town | D31: Cantt | E31: 420 | F31: Wallet | G31: Cancelled
A32: R031 | B32: 19-08-2026 | C32: Iqbal Town | D32: Cantt | E32: 1118 | F32: Card | G32: Completed | H32: 3
A33: R032 | B33: 22-08-2026 | C33: Wapda Town | D33: Faisal Town | E33: 1017 | F33: Card | G33: Completed | H33: 5
A34: R033 | B34: 02-08-2026 | C34: Gulberg | D34: DHA | E34: 974 | F34: Wallet | G34: Completed | H34: 3
A35: R034 | B35: 08-08-2026 | C35: Model Town | D35: Cantt | E35: 1068 | F35: Cash | G35: Completed | H35: 4
A36: R035 | B36: 15-08-2026 | C36: Model Town | D36: Gulberg | E36: 1057 | F36: Wallet | G36: Completed | H36: 5
A37: R036 | B37: 18-08-2026 | C37: Lahore | D37: Gulberg | E37: 634 | F37: Cash | G37: Completed | H37: 4
A38: R037 | B38: 07-08-2026 | C38: Wapda Town | D38: DHA | E38: 487 | F38: Card | G38: Completed | H38: 4
A39: R038 | B39: 09-08-2026 | C39: Iqbal Town | D39: Township | E39: 1016 | F39: Wallet | G39: Cancelled
A40: R039 | B40: 26-08-2026 | C40: Iqbal Town | D40: Model Town | E40: 538 | F40: Card | G40: Completed | H40: 3
...

Sheet Cleaned Data
A1: Ride ID | B1: Date | C1: Pickup Location | D1: Drop-off Location | E1: Fare | F1: Payment Method | G1: Ride Status | H1: Rating
A2: R001 | B2: 2026-08-21 | C2: Gulberg | D2: DHA | E2: 713 | F2: Cash | G2: Completed | H2: 5
A3: R002 | B3: 2026-08-04 | C3: Gulberg | D3: Askari | E3: 215 | F3: Cash | G3: Completed | H3: 3
A4: R003 | B4: 2026-08-17 | C4: Lahore | D4: Cantt | E4: 1009 | F4: Cash | G4: Completed | H4: 4
A5: R004 | B5: 2026-08-26 | C5: Lahore | D5: Model Town | E5: 1015 | F5: Card | G5: Completed | H5: 3
A6: R005 | B6: 2026-08-25 | C6: Bahria Town | D6: Gulberg | E6: 339 | F6: Card | G6: Completed | H6: 4
A7: R006 | B7: 2026-08-20 | C7: Johar Town | D7: DHA | E7: 1090 | F7: Wallet | G7: Completed | H7: 4
A8: R007 | B8: 2026-08-03 | C8: Johar Town | D8: Faisal Town | E8: 543 | F8: Wallet | G8: Completed | H8: 5
A9: R008 | B9: 2026-08-08 | C9: Johar Town | D9: Gulberg | E9: 626 | F9: Cash | G9: Completed | H9: 4
A10: R009 | B10: 2026-08-21 | C10: Bahria Town | D10: Model Town | E10: 908 | F10: Card | G10: Completed | H10: 4
A11: R010 | B11: 2026-08-23 | C11: Gulberg | D11: Model Town | E11: 651 | F11: Cash | G11: Completed | H11: 4
A12: R011 | B12: 2026-08-30 | C12: Model Town | D12: Faisal Town | E12: 264 | F12: Cash | G12: Cancelled
A13: R012 | B13: 2026-08-26 | C13: Bahria Town | D13: Askari | E13: 698 | F13: Cash | G13: Completed | H13: 5
A14: R013 | B14: 2026-08-29 | C14: Bahria Town | D14: Cantt | E14: 1172 | F14: Card | G14: Cancelled
A15: R014 | B15: 2026-08-21 | C15: Iqbal Town | D15: Model Town | E15: 692 | F15: Cash | G15: Completed | H15: 5
A16: R015 | B16: 2026-08-18 | C16: Johar Town | D16: Askari | E16: 967 | F16: Card | G16: Completed | H16: 3
A17: R016 | B17: 2026-08-17 | C17: Iqbal Town | D17: Gulberg | E17: 246 | F17: Cash | G17: Completed | H17: 3
A18: R017 | B18: 2026-08-26 | C18: Wapda Town | D18: Gulberg | E18: 938 | F18: Card | G18: Completed | H18: 4
A19: R018 | B19: 2026-08-17 | C19: Johar Town | D19: DHA | E19: 384 | F19: Wallet | G19: Cancelled
A20: R019 | B20: 2026-08-25 | C20: Johar Town | D20: Faisal Town | E20: 378 | F20: Card | G20: Completed | H20: 4
A21: R020 | B21: 2026-08-01 | C21: Johar Town | D21: Model Town | E21: 1189 | F21: Cash | G21: Cancelled
A22: R021 | B22: 2026-08-10 | C22: Model Town | D22: Model Town | E22: 915 | F22: Cash | G22: Completed | H22: 5
A23: R022 | B23: 2026-08-30 | C23: Lahore | D23: Faisal Town | E23: 1150 | F23: Cash | G23: Completed | H23: 4
A24: R023 | B24: 2026-08-29 | C24: Johar Town | D24: Cantt | E24: 268 | F24: Cash | G24: Cancelled
A25: R024 | B25: 2026-08-03 | C25: Gulberg | D25: Airport | E25: 291 | F25: Wallet | G25: Completed | H25: 3
A26: R025 | B26: 2026-08-22 | C26: Iqbal Town | D26: Model Town | E26: 692 | F26: Wallet | G26: Cancelled
A27: R026 | B27: 2026-08-14 | C27: Model Town | D27: Cantt | E27: 788 | F27: Card | G27: Cancelled
A28: R027 | B28: 2026-08-21 | C28: Bahria Town | D28: Airport | E28: 1074 | F28: Cash | G28: Completed | H28: 3
A29: R028 | B29: 2026-08-11 | C29: Lahore | D29: Cantt | E29: 601 | F29: Cash | G29: Completed | H29: 5
A30: R029 | B30: 2026-08-02 | C30: Model Town | D30: Gulberg | E30: 214 | F30: Card | G30: Completed | H30: 3
A31: R030 | B31: 2026-08-09 | C31: Iqbal Town | D31: Cantt | E31: 420 | F31: Wallet | G31: Cancelled
A32: R031 | B32: 2026-08-19 | C32: Iqbal Town | D32: Cantt | E32: 1118 | F32: Card | G32: Completed | H32: 3
A33: R032 | B33: 2026-08-22 | C33: Wapda Town | D33: Faisal Town | E33: 1017 | F33: Card | G33: Completed | H33: 5
A34: R033 | B34: 2026-08-02 | C34: Gulberg | D34: DHA | E34: 974 | F34: Wallet | G34: Completed | H34: 3
A35: R034 | B35: 2026-08-08 | C35: Model Town | D35: Cantt | E35: 1068 | F35: Cash | G35: Completed | H35: 4
A36: R035 | B36: 2026-08-15 | C36: Model Town | D36: Gulberg | E36: 1057 | F36: Wallet | G36: Completed | H36: 5
A37: R036 | B37: 2026-08-18 | C37: Lahore | D37: Gulberg | E37: 634 | F37: Cash | G37: Completed | H37: 4
A38: R037 | B38: 2026-08-07 | C38: Wapda Town | D38: DHA | E38: 487 | F38: Card | G38: Completed | H38: 4
A39: R038 | B39: 2026-08-09 | C39: Iqbal Town | D39: Township | E39: 1016 | F39: Wallet | G39: Cancelled
A40: R039 | B40: 2026-08-26 | C40: Iqbal Town | D40: Model Town | E40: 538 | F40: Card | G40: Completed | H40: 3
...

Sheet KPI Dashboard
B2: Ride Analytics — KPI Dashboard
B4: Total Rides | C4: Completed Rides | D4: Cancelled Rides | E4: Total Revenue (PKR) | F4: Average Fare (PKR) | G4: Average Rating
B5: =COUNTA('Cleaned Data'!$A$2:$A$121) -> 120 | C5: =COUNTIF('Cleaned Data'!$G$2:$G$121,"Completed") -> 96 | D5: =COUNTIF('Cleaned Data'!$G$2:$G$121,"Cancelled") -> 24 | E5: =SUMIFS('Cleaned Data'!$E$2:$E$121,'Cleaned Data'!$G$2:$G$121,"Completed") -> 65427 | F5: =ROUND(AVERAGEIFS('Cleaned Data'!$E$2:$E$121,'Cleaned Data'!$G$2:$G$121,"Completed"),0) -> 682 | G5: =ROUND(AVERAGE('Cleaned Data'!$H$2:$H$121),2) -> 3.96
B8: Rides & Revenue by Date | F8: Rides by Payment Method | I8: Rides by Status | L8: Top Pickup Locations
B9: Date | C9: Rides | D9: Revenue | F9: Payment Method | G9: Rides | I9: Status | J9: Rides | L9: Pickup Location | M9: Rides
B10: 2026-08-01 | C10: =COUNTIF('Cleaned Data'!$B$2:$B$121,$B10) -> 8 | D10: =SUMIFS('Cleaned Data'!$E$2:$E$121,'Cleaned Data'!$B$2:$B$121,$B10,'Cleaned Data'!$G$2:$G$121,"Completed") -> 3007 | F10: Card | G10: =COUNTIF('Cleaned Data'!$F$2:$F$121,$F10) -> 45 | I10: Cancelled | J10: =COUNTIF('Cleaned Data'!$G$2:$G$121,$I10) -> 24 | L10: Johar Town | M10: =COUNTIF('Cleaned Data'!$C$2:$C$121,$L10) -> 21
B11: 2026-08-02 | C11: =COUNTIF('Cleaned Data'!$B$2:$B$121,$B11) -> 5 | D11: =SUMIFS('Cleaned Data'!$E$2:$E$121,'Cleaned Data'!$B$2:$B$121,$B11,'Cleaned Data'!$G$2:$G$121,"Completed") -> 2335 | F11: Cash | G11: =COUNTIF('Cleaned Data'!$F$2:$F$121,$F11) -> 42 | I11: Completed | J11: =COUNTIF('Cleaned Data'!$G$2:$G$121,$I11) -> 96 | L11: Model Town | M11: =COUNTIF('Cleaned Data'!$C$2:$C$121,$L11) -> 19
B12: 2026-08-03 | C12: =COUNTIF('Cleaned Data'!$B$2:$B$121,$B12) -> 8 | D12: =SUMIFS('Cleaned Data'!$E$2:$E$121,'Cleaned Data'!$B$2:$B$121,$B12,'Cleaned Data'!$G$2:$G$121,"Completed") -> 4342 | F12: Wallet | G12: =COUNTIF('Cleaned Data'!$F$2:$F$121,$F12) -> 33 | L12: Wapda Town | M12: =COUNTIF('Cleaned Data'!$C$2:$C$121,$L12) -> 18
B13: 2026-08-04 | C13: =COUNTIF('Cleaned Data'!$B$2:$B$121,$B13) -> 2 | D13: =SUMIFS('Cleaned Data'!$E$2:$E$121,'Cleaned Data'!$B$2:$B$121,$B13,'Cleaned Data'!$G$2:$G$121,"Completed") -> 889 | L13: Gulberg | M13: =COUNTIF('Cleaned Data'!$C$2:$C$121,$L13) -> 15
B14: 2026-08-05 | C14: =COUNTIF('Cleaned Data'!$B$2:$B$121,$B14) -> 2 | D14: =SUMIFS('Cleaned Data'!$E$2:$E$121,'Cleaned Data'!$B$2:$B$121,$B14,'Cleaned Data'!$G$2:$G$121,"Completed") -> 1576 | L14: Bahria Town | M14: =COUNTIF('Cleaned Data'!$C$2:$C$121,$L14) -> 15
B15: 2026-08-06 | C15: =COUNTIF('Cleaned Data'!$B$2:$B$121,$B15) -> 2 | D15: =SUMIFS('Cleaned Data'!$E$2:$E$121,'Cleaned Data'!$B$2:$B$121,$B15,'Cleaned Data'!$G$2:$G$121,"Completed") -> 1536 | L15: Iqbal Town | M15: =COUNTIF('Cleaned Data'!$C$2:$C$121,$L15) -> 15
B16: 2026-08-07 | C16: =COUNTIF('Cleaned Data'!$B$2:$B$121,$B16) -> 2 | D16: =SUMIFS('Cleaned Data'!$E$2:$E$121,'Cleaned Data'!$B$2:$B$121,$B16,'Cleaned Data'!$G$2:$G$121,"Completed") -> 1471 | L16: Lahore | M16: =COUNTIF('Cleaned Data'!$C$2:$C$121,$L16) -> 10
B17: 2026-08-08 | C17: =COUNTIF('Cleaned Data'!$B$2:$B$121,$B17) -> 5 | D17: =SUMIFS('Cleaned Data'!$E$2:$E$121,'Cleaned Data'!$B$2:$B$121,$B17,'Cleaned Data'!$G$2:$G$121,"Completed") -> 2553 | L17: DHA | M17: =COUNTIF('Cleaned Data'!$C$2:$C$121,$L17) -> 7
B18: 2026-08-09 | C18: =COUNTIF('Cleaned Data'!$B$2:$B$121,$B18) -> 7 | D18: =SUMIFS('Cleaned Data'!$E$2:$E$121,'Cleaned Data'!$B$2:$B$121,$B18,'Cleaned Data'!$G$2:$G$121,"Completed") -> 2874
B19: 2026-08-10 | C19: =COUNTIF('Cleaned Data'!$B$2:$B$121,$B19) -> 5 | D19: =SUMIFS('Cleaned Data'!$E$2:$E$121,'Cleaned Data'!$B$2:$B$121,$B19,'Cleaned Data'!$G$2:$G$121,"Completed") -> 1960
B20: 2026-08-11 | C20: =COUNTIF('Cleaned Data'!$B$2:$B$121,$B20) -> 4 | D20: =SUMIFS('Cleaned Data'!$E$2:$E$121,'Cleaned Data'!$B$2:$B$121,$B20,'Cleaned Data'!$G$2:$G$121,"Completed") -> 2926
B21: 2026-08-12 | C21: =COUNTIF('Cleaned Data'!$B$2:$B$121,$B21) -> 1 | D21: =SUMIFS('Cleaned Data'!$E$2:$E$121,'Cleaned Data'!$B$2:$B$121,$B21,'Cleaned Data'!$G$2:$G$121,"Completed") -> 606
B22: 2026-08-13 | C22: =COUNTIF('Cleaned Data'!$B$2:$B$121,$B22) -> 2 | D22: =SUMIFS('Cleaned Data'!$E$2:$E$121,'Cleaned Data'!$B$2:$B$121,$B22,'Cleaned Data'!$G$2:$G$121,"Completed") -> 766
B23: 2026-08-14 | C23: =COUNTIF('Cleaned Data'!$B$2:$B$121,$B23) -> 2 | D23: =SUMIFS('Cleaned Data'!$E$2:$E$121,'Cleaned Data'!$B$2:$B$121,$B23,'Cleaned Data'!$G$2:$G$121,"Completed") -> 353
B24: 2026-08-15 | C24: =COUNTIF('Cleaned Data'!$B$2:$B$121,$B24) -> 1 | D24: =SUMIFS('Cleaned Data'!$E$2:$E$121,'Cleaned Data'!$B$2:$B$121,$B24,'Cleaned Data'!$G$2:$G$121,"Completed") -> 1057
B25: 2026-08-16 | C25: =COUNTIF('Cleaned Data'!$B$2:$B$121,$B25) -> 3 | D25: =SUMIFS('Cleaned Data'!$E$2:$E$121,'Cleaned Data'!$B$2:$B$121,$B25,'Cleaned Data'!$G$2:$G$121,"Completed") -> 2713
B26: 2026-08-17 | C26: =COUNTIF('Cleaned Data'!$B$2:$B$121,$B26) -> 5 | D26: =SUMIFS('Cleaned Data'!$E$2:$E$121,'Cleaned Data'!$B$2:$B$121,$B26,'Cleaned Data'!$G$2:$G$121,"Completed") -> 2641
B27: 2026-08-18 | C27: =COUNTIF('Cleaned Data'!$B$2:$B$121,$B27) -> 5 | D27: =SUMIFS('Cleaned Data'!$E$2:$E$121,'Cleaned Data'!$B$2:$B$121,$B27,'Cleaned Data'!$G$2:$G$121,"Completed") -> 3014
B28: 2026-08-19 | C28: =COUNTIF('Cleaned Data'!$B$2:$B$121,$B28) -> 8 | D28: =SUMIFS('Cleaned Data'!$E$2:$E$121,'Cleaned Data'!$B$2:$B$121,$B28,'Cleaned Data'!$G$2:$G$121,"Completed") -> 4346
B29: 2026-08-20 | C29: =COUNTIF('Cleaned Data'!$B$2:$B$121,$B29) -> 3 | D29: =SUMIFS('Cleaned Data'!$E$2:$E$121,'Cleaned Data'!$B$2:$B$121,$B29,'Cleaned Data'!$G$2:$G$121,"Completed") -> 1779
... B39: 2026-08-30 | C39: =COUNTIF('Cleaned Data'!$B$2:$B$121,$B39) -> 5 | D39: =SUMIFS('Cleaned Data'!$E$2:$E$121,'Cleaned Data'!$B$2:$B$121,$B39,'Cleaned Data'!$G$2:$G$121,"Completed") -> 2106

Sheet Charts
B2: Ride Analytics — Charts

Sheet Insights
B2: Business Insights
B4: 1. Out of 120 cleaned rides, 96 were completed and 24 were cancelled — a 20% cancellation rate worth investigating.
B5: 2. Card is the most-used payment method (45 rides), narrowly ahead of Cash (42) and Wallet (33).
B6: 3. Johar Town is the busiest pickup location with 21 rides, followed by Model Town (19) and Wapda Town (18).
B7: 4. Total revenue from completed rides is PKR 65,427, with an average fare of about PKR 682 per completed ride.
B8: 5. Average customer rating across completed rides is 3.96 out of 5, suggesting room to improve service quality.
